Workbook
Name pdwnrspbb4tbipnl: vwretd_sp500!$A$1:$B$6542

Sheet all_series
A1: date | B1: sp500_index_pct_return_d | C1: ice_bond_pct_return_d | D1: tr_10y_d | E1: tr_3m_d | F1: ffer_d
A2: 36164 | B2: -0.00083076138 | C2: 0 | D2: 4.69 | E2: 4.38 | F2: =_xlfn.XLOOKUP(A2,'Daily_7-Day_FedFundER'!A:A,'Daily_7-Day_FedFundER'!B:B) -> 5.04
A3: 36165 | B3: 0.011887922 | C3: -0.0038382427 | D3: 4.74 | E3: 4.37 | F3: =_xlfn.XLOOKUP(A3,'Daily_7-Day_FedFundER'!A:A,'Daily_7-Day_FedFundER'!B:B) -> 4.54
A4: 36166 | B4: 0.021142805 | C4: 0.0023908555 | D4: 4.73 | E4: 4.36 | F4: =_xlfn.XLOOKUP(A4,'Daily_7-Day_FedFundER'!A:A,'Daily_7-Day_FedFundER'!B:B) -> 4.23
A5: 36167 | B5: -0.00079928638 | C5: -0.002690689 | D5: 4.77 | E5: 4.33 | F5: =_xlfn.XLOOKUP(A5,'Daily_7-Day_FedFundER'!A:A,'Daily_7-Day_FedFundER'!B:B) -> 4.49
A6: 36168 | B6: 0.0046039148 | C6: -0.0025793572 | D6: 4.86 | E6: 4.37 | F6: =_xlfn.XLOOKUP(A6,'Daily_7-Day_FedFundER'!A:A,'Daily_7-Day_FedFundER'!B:B) -> 4.74
A7: 36171 | B7: -0.0049818803 | C7: -0.001506039 | D7: 4.9 | E7: 4.39 | F7: =_xlfn.XLOOKUP(A7,'Daily_7-Day_FedFundER'!A:A,'Daily_7-Day_FedFundER'!B:B) -> 5.17
A8: 36172 | B8: -0.01819731 | C8: 0.0050310097 | D8: 4.82 | E8: 4.37 | F8: =_xlfn.XLOOKUP(A8,'Daily_7-Day_FedFundER'!A:A,'Daily_7-Day_FedFundER'!B:B) -> 4.78
A9: 36173 | B9: -0.005759516 | C9: 0.0042060781 | D9: 4.74 | E9: 4.34 | F9: =_xlfn.XLOOKUP(A9,'Daily_7-Day_FedFundER'!A:A,'Daily_7-Day_FedFundER'!B:B) -> 4.62
A10: 36174 | B10: -0.015793006 | C10: 0.0066169819 | D10: 4.63 | E10: 4.33 | F10: =_xlfn.XLOOKUP(A10,'Daily_7-Day_FedFundER'!A:A,'Daily_7-Day_FedFundER'!B:B) -> 4.82
A11: 36175 | B11: 0.023000877 | C11: -0.0037702308 | D11: 4.66 | E11: 4.33 | F11: =_xlfn.XLOOKUP(A11,'Daily_7-Day_FedFundER'!A:A,'Daily_7-Day_FedFundER'!B:B) -> 4.68
A12: 36179 | B12: 0.0075996441 | C12: -0.0016853822 | D12: 4.71 | E12: 4.29 | F12: =_xlfn.XLOOKUP(A12,'Daily_7-Day_FedFundER'!A:A,'Daily_7-Day_FedFundER'!B:B) -> 4.55
A13: 36180 | B13: 0.0023643219 | C13: -0.001668597 | D13: 4.76 | E13: 4.26 | F13: =_xlfn.XLOOKUP(A13,'Daily_7-Day_FedFundER'!A:A,'Daily_7-Day_FedFundER'!B:B) -> 4.41
... A6542: 45657 | B6542: -0.00339214 | C6542: -0.001766546 | D6542: 4.58 | E6542: 4.23 | F6542: =_xlfn.XLOOKUP(A6542,'Daily_7-Day_FedFundER'!A:A,'Daily_7-Day_FedFundER'!B:B) -> 4.33

Sheet Daily_DGS10YR
A1: observation_date | B1: DGS10
A2: 36164 | B2: 4.69
A3: 36165 | B3: 4.74
A4: 36166 | B4: 4.73
A5: 36167 | B5: 4.77
A6: 36168 | B6: 4.86
A7: 36171 | B7: 4.9
A8: 36172 | B8: 4.82
A9: 36173 | B9: 4.74
A10: 36174 | B10: 4.63
A11: 36175 | B11: 4.66
A12: 36178
A13: 36179 | B13: 4.71
A14: 36180 | B14: 4.76
A15: 36181 | B15: 4.7
A16: 36182 | B16: 4.64
A17: 36185 | B17: 4.67
A18: 36186 | B18: 4.69
A19: 36187 | B19: 4.68
A20: 36188 | B20: 4.67
A21: 36189 | B21: 4.66
A22: 36192 | B22: 4.75
A23: 36193 | B23: 4.79
A24: 36194 | B24: 4.83
... A31: 36203 | B31: 5.06
A32: 36206
A33: 36207 | B33: 5.03
A34: 36208 | B34: 4.98
A35: 36209 | B35: 5.04
A36: 36210 | B36: 5.07
A37: 36213 | B37: 5.03
A38: 36214 | B38: 5.1
A39: 36215 | B39: 5.18
A40: 36216 | B40: 5.32
A41: 36217 | B41: 5.29
A42: 36220 | B42: 5.4
A43: 36221 | B43: 5.35
A44: 36222 | B44: 5.39
... A106: 36308 | B106: 5.64
A107: 36311
...

Sheet Daily_DTB3M
A1: observation_date | B1: DTB3
A2: 36164 | B2: 4.38
A3: 36165 | B3: 4.37
A4: 36166 | B4: 4.36
A5: 36167 | B5: 4.33
A6: 36168 | B6: 4.37
A7: 36171 | B7: 4.39
A8: 36172 | B8: 4.37
A9: 36173 | B9: 4.34
A10: 36174 | B10: 4.33
A11: 36175 | B11: 4.33
A12: 36178
A13: 36179 | B13: 4.29
A14: 36180 | B14: 4.26
A15: 36181 | B15: 4.22
A16: 36182 | B16: 4.26
A17: 36185 | B17: 4.31
A18: 36186 | B18: 4.35
A19: 36187 | B19: 4.36
A20: 36188 | B20: 4.38
A21: 36189 | B21: 4.37
A22: 36192 | B22: 4.42
A23: 36193 | B23: 4.42
A24: 36194 | B24: 4.37
... A31: 36203 | B31: 4.43
A32: 36206
A33: 36207 | B33: 4.41
A34: 36208 | B34: 4.41
A35: 36209 | B35: 4.42
A36: 36210 | B36: 4.45
A37: 36213 | B37: 4.5
A38: 36214 | B38: 4.54
A39: 36215 | B39: 4.55
A40: 36216 | B40: 4.51
A41: 36217 | B41: 4.55
A42: 36220 | B42: 4.58
A43: 36221 | B43: 4.53
A44: 36222 | B44: 4.49
... A106: 36308 | B106: 4.53
A107: 36311
...

Sheet vwretd_sp500
A1: Daily Calendar Date | B1: Value-weighted return including dividends
A2: 36164 | B2: -0.00083076138
A3: 36165 | B3: 0.011887922
A4: 36166 | B4: 0.021142805
A5: 36167 | B5: -0.00079928638
A6: 36168 | B6: 0.0046039148
A7: 36171 | B7: -0.0049818803
A8: 36172 | B8: -0.01819731
A9: 36173 | B9: -0.005759516
A10: 36174 | B10: -0.015793006
A11: 36175 | B11: 0.023000877
A12: 36179 | B12: 0.0075996441
A13: 36180 | B13: 0.0023643219
... A6542: 45657 | B6542: -0.00339214

Sheet icebond_total_ind_ret
A1: observation_date | B1: BAMLCC0A0CMTRIV | C1: Return
A2: 36160 | B2: 1017.16
A3: 36161 | C3: =IFERROR(B3/B2-1, 0) -> -1
A4: 36164 | B4: 1016.09 | C4: =IFERROR(B4/B3-1, 0) -> 0
A5: 36165 | B5: 1012.19 | C5: =IFERROR(B5/B4-1, 0) -> -0.0038382427
A6: 36166 | B6: 1014.61 | C6: =IFERROR(B6/B5-1, 0) -> 0.0023908555
A7: 36167 | B7: 1011.88 | C7: =IFERROR(B7/B6-1, 0) -> -0.002690689
A8: 36168 | B8: 1009.27 | C8: =IFERROR(B8/B7-1, 0) -> -0.0025793572
A9: 36171 | B9: 1007.75 | C9: =IFERROR(B9/B8-1, 0) -> -0.001506039
A10: 36172 | B10: 1012.82 | C10: =IFERROR(B10/B9-1, 0) -> 0.0050310097
A11: 36173 | B11: 1017.08 | C11: =IFERROR(B11/B10-1, 0) -> 0.0042060781
A12: 36174 | B12: 1023.81 | C12: =IFERROR(B12/B11-1, 0) -> 0.0066169819
A13: 36175 | B13: 1019.95 | C13: =IFERROR(B13/B12-1, 0) -> -0.0037702308
A14: 36178 | B14: 1020.54 | C14: =IFERROR(B14/B13-1, 0) -> 0.00057845973
A15: 36179 | B15: 1018.82 | C15: =IFERROR(B15/B14-1, 0) -> -0.0016853822
... A346: 36636 | B346: 1015.86 | C346: =IFERROR(B346/B345-1, 0) -> 0.00036435612
A347: 36637 | C347: =IFERROR(B347/B346-1, 0) -> -1
A348: 36640 | B348: 1016.81 | C348: =IFERROR(B348/B347-1, 0) -> 0
A349: 36641 | B349: 1010.11 | C349: =IFERROR(B349/B348-1, 0) -> -0.006589235
A350: 36642 | B350: 1009.37 | C350: =IFERROR(B350/B349-1, 0) -> -0.00073259348
A351: 36643 | B351: 1002.95 | C351: =IFERROR(B351/B350-1, 0) -> -0.006360403
A352: 36644 | B352: 1000.49 | C352: =IFERROR(B352/B351-1, 0) -> -0.0024527643
A353: 36646 | B353: 1000.92 | C353: =IFERROR(B353/B352-1, 0) -> 0.0004297894
A354: 36647 | B354: 999.67 | C354: =IFERROR(B354/B353-1, 0) -> -0.0012488511
A355: 36648 | B355: 997.37 | C355: =IFERROR(B355/B354-1, 0) -> -0.0023007593
A356: 36649 | B356: 993.73 | C356: =IFERROR(B356/B355-1, 0) -> -0.0036495984
A357: 36650 | B357: 990.95 | C357: =IFERROR(B357/B356-1, 0) -> -0.0027975406
A358: 36651 | B358: 989.01 | C358: =IFERROR(B358/B357-1, 0) -> -0.0019577173
A359: 36654 | B359: 985.78 | C359: =IFERROR(B359/B358-1, 0) -> -0.0032658922
... A524: 36882 | B524: 1094.13 | C524: =IFERROR(B524/B523-1, 0) -> 0.00059443245
A525: 36885 | C525: =IFERROR(B525/B524-1, 0) -> -1
A526: 36886 | B526: 1093.46 | C526: =IFERROR(B526/B525-1, 0) -> 0
A527: 36887 | B527: 1090.07 | C527: =IFERROR(B527/B526-1, 0) -> -0.0031002506
A528: 36888 | B528: 1088.24 | C528: =IFERROR(B528/B527-1, 0) -> -0.0016787913
A529: 36889 | B529: 1088.72 | C529: =IFERROR(B529/B528-1, 0) -> 0.00044107917
A530: 36891 | B530: 1089.13 | C530: =IFERROR(B530/B529-1, 0) -> 0.00037658902
A531: 36892 | C531: =IFERROR(B531/B530-1, 0) -> -1
A532: 36893 | B532: 1099.54 | C532: =IFERROR(B532/B531-1, 0) -> 0
A533: 36894 | B533: 1091.13 | C533: =IFERROR(B533/B532-1, 0) -> -0.0076486531
A534: 36895 | B534: 1096.91 | C534: =IFERROR(B534/B533-1, 0) -> 0.0052972606
...

Sheet icebond_total_return_pct
A1: date | B1: icebond_ret
A2: 36161 | B2: -1
A3: 36164 | B3: 0
A4: 36165 | B4: -0.0038382427
A5: 36166 | B5: 0.0023908555
A6: 36167 | B6: -0.002690689
A7: 36168 | B7: -0.0025793572
A8: 36171 | B8: -0.001506039
A9: 36172 | B9: 0.0050310097
A10: 36173 | B10: 0.0042060781
A11: 36174 | B11: 0.0066169819
A12: 36175 | B12: -0.0037702308
A13: 36178 | B13: 0.00057845973
... A6872: 45657 | B6872: -0.001766546

Sheet Daily_7-Day_FedFundER
A1: observation_date | B1: DFF
A2: 36161 | B2: 4.07
A3: 36162 | B3: 4.07
A4: 36163 | B4: 4.07
A5: 36164 | B5: 5.04
A6: 36165 | B6: 4.54
A7: 36166 | B7: 4.23
A8: 36167 | B8: 4.49
A9: 36168 | B9: 4.74
A10: 36169 | B10: 4.74
A11: 36170 | B11: 4.74
A12: 36171 | B12: 5.17
A13: 36172 | B13: 4.78
... A9498: 45657 | B9498: 4.33
